Workbook

Sheet Cover
B2: Project Harvest: Demo Target Co. (synthetic)
B3: Preliminary valuation model (illustrative, educational)
B4: Source: SYNTHETIC DEMO DATA
B7: Inputs | C7: Market data and all assumptions (blue cells)
B8: Comps | C8: Trading comparables with live multiple and quartile formulas
B9: WACC | C9: Beta unlevering/relevering and cost of capital build
B10: DCF | C10: 5-year projections, perpetuity and exit valuation, live sensitivity grids
B11: LBO | C11: Sponsor ability-to-pay: entry price input, debt schedule, IRR
B12: Football Field | C12: Valuation summary and chart
B14: Colour code
B15: Blue = hard-coded input
B16: Black = formula
B17: Green = link to another sheet

Sheet Inputs
B2: Inputs & assumptions
B4: Target market data ($mm, except per share)
B5: Share price | C5: 20
B6: Diluted shares (mm) | C6: 853.43188
B7: Total debt | C7: 6188.9874
B8: Cash & equivalents | C8: 468.67216
B9: Minority interest | C9: 0
B10: LTM revenue | C10: 11833.972
B11: LTM EBITDA | C11: 2083.6258
B12: NTM EPS (consensus) | C12: 1.2610909
B13: Market capitalisation | C13: =Inputs!$C$5*Inputs!$C$6 -> 17068.638
B14: Enterprise value | C14: =C13+C7-C8+C9 -> 22788.953
B16: Valuation assumptions
B17: Risk-free rate | C17: 0.042
B18: Equity risk premium | C18: 0.045
B19: Tax rate | C19: 0.23
B20: Terminal growth | C20: 0.025
B21: Exit multiple (EV/EBITDA) | C21: 10.620211
B22: Pre-tax cost of debt (synthetic rating) | C22: 0.0528
B24: LBO assumptions
B25: Entry leverage (x LTM EBITDA) | C25: 5
B26: Cost of debt | C26: 0.085
B27: Transaction fees (% EV) | C27: 0.02
B28: Offer price per share (solved at target IRR) | C28: 13.133348
B30: Operating drivers | C30: FY2026E | D30: FY2027E | E30: FY2028E | F30: FY2029E | G30: FY2030E
B31: Revenue growth | C31: 0.021814089 | D31: 0.022610567 | E31: 0.023407045 | F31: 0.024203522 | G31: 0.025
B32: EBITDA margin | C32: 0.17253664 | D32: 0.17253664 | E32: 0.17253664 | F32: 0.17253664 | G32: 0.17253664
B33: D&A % revenue | C33: 0.035 | D33: 0.035 | E33: 0.035 | F33: 0.035 | G33: 0.035
B34: Capex % revenue | C34: 0.037 | D34: 0.037 | E34: 0.037 | F34: 0.037 | G34: 0.037
B35: NWC % incr. revenue | C35: 0.1 | D35: 0.1 | E35: 0.1 | F35: 0.1 | G35: 0.1
B37: Base year revenue (FY2025A) | C37: 11716.804

Sheet Comps
B2: Trading comparables ($mm, except per share)
B4: Ticker | C4: Company | D4: Price | E4: Shares | F4: Debt | G4: Cash | H4: Minority | I4: Revenue LTM | J4: EBITDA LTM | K4: EPS LTM | L4: EPS NTM | M4: Mkt cap | N4: EV | O4: EV/Rev | P4: EV/EBITDA | Q4: P/E LTM | R4: P/E NTM
B5: PEER-A.DEMO | C5: Peer-A Corp. (synthetic) | D5: 37 | E5: 835.73007 | F5: 11094.56 | G5: 777.27325 | H5: 0 | I5: 19723.309 | J5: 3883.096 | K5: 2.4229032 | L5: 2.5078839 | M5: =D5*E5 -> 30922.013 | N5: =M5+F5-G5+H5 -> 41239.299 | O5: =IF(I5>0,N5/I5,"n.m.") -> 2.0908915 | P5: =IF(AND(J5>0,N5/J5<100),N5/J5,"n.m.") -> 10.620211 | Q5: =IF(AND(K5>0,D5/K5<100),D5/K5,"n.m.") -> 15.270936 | R5: =IF(AND(L5>0,D5/L5<100),D5/L5,"n.m.") -> 14.753474
B6: PEER-B.DEMO | C6: Peer-B Corp. (synthetic) | D6: 54 | E6: 276.11828 | F6: 5404.4003 | G6: 381.79189 | H6: 0 | I6: 9759.5551 | J6: 1782.5804 | K6: 3.2479412 | L6: 3.3858 | M6: =D6*E6 -> 14910.387 | N6: =M6+F6-G6+H6 -> 19932.996 | O6: =IF(I6>0,N6/I6,"n.m.") -> 2.0424082 | P6: =IF(AND(J6>0,N6/J6<100),N6/J6,"n.m.") -> 11.182102 | Q6: =IF(AND(K6>0,D6/K6<100),D6/K6,"n.m.") -> 16.625917 | R6: =IF(AND(L6>0,D6/L6<100),D6/L6,"n.m.") -> 15.948963
B7: PEER-C.DEMO | C7: Peer-C Corp. (synthetic) | D7: 71 | E7: 158.18467 | F7: 6435.5847 | G7: 341.73078 | H7: 0 | I7: 8650.0604 | J7: 1810.0082 | K7: 5.751 | L7: 5.93844 | M7: =D7*E7 -> 11231.112 | N7: =M7+F7-G7+H7 -> 17324.966 | O7: =IF(I7>0,N7/I7,"n.m.") -> 2.0028722 | P7: =IF(AND(J7>0,N7/J7<100),N7/J7,"n.m.") -> 9.5717609 | Q7: =IF(AND(K7>0,D7/K7<100),D7/K7,"n.m.") -> 12.345679 | R7: =IF(AND(L7>0,D7/L7<100),D7/L7,"n.m.") -> 11.956002
B8: PEER-D.DEMO | C8: Peer-D Corp. (synthetic) | D8: 88 | E8: 150.92399 | F8: 1721.6844 | G8: 475.77581 | H8: 0 | I8: 11953.867 | J8: 1441.9107 | K8: 4.7805405 | L8: 4.9004108 | M8: =D8*E8 -> 13281.311 | N8: =M8+F8-G8+H8 -> 14527.22 | O8: =IF(I8>0,N8/I8,"n.m.") -> 1.2152736 | P8: =IF(AND(J8>0,N8/J8<100),N8/J8,"n.m.") -> 10.074979 | Q8: =IF(AND(K8>0,D8/K8<100),D8/K8,"n.m.") -> 18.40796 | R8: =IF(AND(L8>0,D8/L8<100),D8/L8,"n.m.") -> 17.957678
B9: PEER-E.DEMO | C9: Peer-E Corp. (synthetic) | D9: 105 | E9: 351.9087 | F9: 20863.187 | G9: 1047.4447 | H9: 0 | I9: 26055.186 | J9: 6290.567 | K9: 9.4977273 | L9: 9.639 | M9: =D9*E9 -> 36950.413 | N9: =M9+F9-G9+H9 -> 56766.156 | O9: =IF(I9>0,N9/I9,"n.m.") -> 2.1786893 | P9: =IF(AND(J9>0,N9/J9<100),N9/J9,"n.m.") -> 9.0240125 | Q9: =IF(AND(K9>0,D9/K9<100),D9/K9,"n.m.") -> 11.055276 | R9: =IF(AND(L9>0,D9/L9<100),D9/L9,"n.m.") -> 10.893246
B10: PEER-F.DEMO | C10: Peer-F Corp. (synthetic) | D10: 32 | E10: 557.19197 | F10: 3583.9001 | G10: 267.87831 | H10: 0 | I10: 6864.3818 | J10: 1412.8837 | K10: 1.3666667 | L10: 1.428 | M10: =D10*E10 -> 17830.143 | N10: =M10+F10-G10+H10 -> 21146.165 | O10: =IF(I10>0,N10/I10,"n.m.") -> 3.0805636 | P10: =IF(AND(J10>0,N10/J10<100),N10/J10,"n.m.") -> 14.966671 | Q10: =IF(AND(K10>0,D10/K10<100),D10/K10,"n.m.") -> 23.414634 | R10: =IF(AND(L10>0,D10/L10<100),D10/L10,"n.m.") -> 22.408964
B11: PEER-G.DEMO | C11: Peer-G Corp. (synthetic) | D11: 49 | E11: 208.87101 | F11: 6626.0652 | G11: 318.18138 | H11: 0 | I11: 8193.1706 | J11: 1483.6624 | K11: 3.154375 | L11: 3.311175 | M11: =D11*E11 -> 10234.68 | N11: =M11+F11-G11+H11 -> 16542.563 | O11: =IF(I11>0,N11/I11,"n.m.") -> 2.0190674 | P11: =IF(AND(J11>0,N11/J11<100),N11/J11,"n.m.") -> 11.149816 | Q11: =IF(AND(K11>0,D11/K11<100),D11/K11,"n.m.") -> 15.533981 | R11: =IF(AND(L11>0,D11/L11<100),D11/L11,"n.m.") -> 14.798372
C13: Mean | O13: =AVERAGE(O5:O11) -> 2.0899666 | P13: =AVERAGE(P5:P11) -> 10.941365 | Q13: =AVERAGE(Q5:Q11) -> 16.093483 | R13: =AVERAGE(R5:R11) -> 15.530957
C14: Median | O14: =MEDIAN(O5:O11) -> 2.0424082 | P14: =MEDIAN(P5:P11) -> 10.620211 | Q14: =MEDIAN(Q5:Q11) -> 15.533981 | R14: =MEDIAN(R5:R11) -> 14.798372
C15: 25th percentile | O15: =QUARTILE(O5:O11,1) -> 2.0109698 | P15: =QUARTILE(P5:P11,1) -> 9.8233698 | Q15: =QUARTILE(Q5:Q11,1) -> 13.808307 | R15: =QUARTILE(R5:R11,1) -> 13.354738
C16: 75th percentile | O16: =QUARTILE(O5:O11,3) -> 2.1347904 | P16: =QUARTILE(P5:P11,3) -> 11.165959 | Q16: =QUARTILE(Q5:Q11,3) -> 17.516939 | R16: =QUARTILE(R5:R11,3) -> 16.953321
C18: Implied value per share | D18: Low (25th) | E18: High (75th)
C19: EV / LTM EBITDA | D19: =(P15*Inputs!$C$11-(Inputs!$C$7-Inputs!$C$8+Inputs!$C$9))/Inputs!$C$6 -> 17.280713 | E19: =(P16*Inputs!$C$11-(Inputs!$C$7-Inputs!$C$8+Inputs!$C$9))/Inputs!$C$6 -> 20.5586
C20: P / NTM EPS | D20: =R15*Inputs!$C$12 -> 16.841539 | E20: =R16*Inputs!$C$12 -> 21.379679

Sheet WACC
B2: Cost of capital
B4: Peer | C4: Adj. beta (Blume) | D4: Debt | E4: Mkt cap | F4: D/E | G4: Unlevered beta
B5: PEER-A.DEMO | C5: 0.88680241 | D5: 11094.56 | E5: 30922.013 | F5: =D5/E5 -> 0.35879165 | G5: =C5/(1+(1-Inputs!$C$19)*F5) -> 0.69483942
B6: PEER-B.DEMO | C6: 0.90928974 | D6: 5404.4003 | E6: 14910.387 | F6: =D6/E6 -> 0.36245875 | G6: =C6/(1+(1-Inputs!$C$19)*F6) -> 0.71088621
B7: PEER-C.DEMO | C7: 0.80321414 | D7: 6435.5847 | E7: 11231.112 | F7: =D7/E7 -> 0.57301404 | G7: =C7/(1+(1-Inputs!$C$19)*F7) -> 0.55731511
B8: PEER-D.DEMO | C8: 0.84155635 | D8: 1721.6844 | E8: 13281.311 | F8: =D8/E8 -> 0.12963211 | G8: =C8/(1+(1-Inputs!$C$19)*F8) -> 0.76517872
B9: PEER-E.DEMO | C9: 0.78611405 | D9: 20863.187 | E9: 36950.413 | F9: =D9/E9 -> 0.56462663 | G9: =C9/(1+(1-Inputs!$C$19)*F9) -> 0.54790535
B10: PEER-F.DEMO | C10: 0.95430188 | D10: 3583.9001 | E10: 17830.143 | F10: =D10/E10 -> 0.20100232 | G10: =C10/(1+(1-Inputs!$C$19)*F10) -> 0.82639868
B11: PEER-G.DEMO | C11: 1.0208854 | D11: 6626.0652 | E11: 10234.68 | F11: =D11/E11 -> 0.64741305 | G11: =C11/(1+(1-Inputs!$C$19)*F11) -> 0.68126791
B13: Median unlevered beta | C13: =MEDIAN(G5:G11) -> 0.69483942
B14: Target D/E (market) | C14: =Inputs!$C$7/Inputs!$C$13 -> 0.36259411
B15: Relevered beta | C15: =C13*(1+(1-Inputs!$C$19)*C14) -> 0.88883682
B16: Risk-free rate | C16: =Inputs!$C$17 -> 0.042
B17: Equity risk premium | C17: =Inputs!$C$18 -> 0.045
B18: Cost of equity | C18: =C16+C15*C17 -> 0.081997657
B19: Pre-tax cost of debt | C19: =Inputs!$C$22 -> 0.0528
B20: After-tax cost of debt | C20: =C19*(1-Inputs!$C$19) -> 0.040656
B21: Equity weight E/(D+E) | C21: =Inputs!$C$13/(Inputs!$C$13+Inputs!$C$7) -> 0.73389426
B22: WACC | C22: =C21*C18+(1-C21)*C20 -> 0.070996405
B25: Regression betas (raw): 2y weekly 0.68 (R² 0.28), 5y monthly 0.71 (R² 0.32)
B26: Synthetic rating A from interest coverage 5.3x (Damodaran table, approximate spreads)

Sheet DCF
B2: Discounted cash flow ($mm)
C4: FY2025A | D4: FY2026E | E4: FY2027E | F4: FY2028E | G4: FY2029E | H4: FY2030E
B5: Period (mid-year) | D5: 1 | E5: 2 | F5: 3 | G5: 4 | H5: 5
B7: Revenue | C7: =Inputs!$C$37 -> 11716.804 | D7: =C7*(1+D8) -> 11972.395 | E7: =D7*(1+E8) -> 12243.098 | F7: =E7*(1+F8) -> 12529.673 | G7: =F7*(1+G8) -> 12832.935 | H7: =G7*(1+H8) -> 13153.758
B8: % growth | D8: =Inputs!C31 -> 0.021814089 | E8: =Inputs!D31 -> 0.022610567 | F8: =Inputs!E31 -> 0.023407045 | G8: =Inputs!F31 -> 0.024203522 | H8: =Inputs!G31 -> 0.025
B9: EBITDA | D9: =D7*D10 -> 2065.6769 | E9: =E7*E10 -> 2112.383 | F9: =F7*F10 -> 2161.8277 | G9: =G7*G10 -> 2214.1515 | H9: =H7*H10 -> 2269.5053
B10: % margin | D10: =Inputs!C32 -> 0.17253664 | E10: =Inputs!D32 -> 0.17253664 | F10: =Inputs!E32 -> 0.17253664 | G10: =Inputs!F32 -> 0.17253664 | H10: =Inputs!G32 -> 0.17253664
B11: D&A | D11: =D7*Inputs!C33 -> 419.03384 | E11: =E7*Inputs!D33 -> 428.50844 | F11: =F7*Inputs!E33 -> 438.53855 | G11: =G7*Inputs!F33 -> 449.15273 | H11: =H7*Inputs!G33 -> 460.38155
B12: EBIT | D12: =D9-D11 -> 1646.6431 | E12: =E9-E11 -> 1683.8746 | F12: =F9-F11 -> 1723.2891 | G12: =G9-G11 -> 1764.9988 | H12: =H9-H11 -> 1809.1238
B13: Taxes | D13: =-D12*Inputs!$C$19 -> -378.7279 | E13: =-E12*Inputs!$C$19 -> -387.29116 | F13: =-F12*Inputs!$C$19 -> -396.3565 | G13: =-G12*Inputs!$C$19 -> -405.94972 | H13: =-H12*Inputs!$C$19 -> -416.09846
B14: NOPAT | D14: =D12+D13 -> 1267.9152 | E14: =E12+E13 -> 1296.5834 | F14: =F12+F13 -> 1326.9326 | G14: =G12+G13 -> 1359.0491 | H14: =H12+H13 -> 1393.0253
B15: (+) D&A | D15: =D11 -> 419.03384 | E15: =E11 -> 428.50844 | F15: =F11 -> 438.53855 | G15: =G11 -> 449.15273 | H15: =H11 -> 460.38155
B16: (-) Capex | D16: =-D7*Inputs!C34 -> -442.97863 | E16: =-E7*Inputs!D34 -> -452.99463 | F16: =-F7*Inputs!E34 -> -463.5979 | G16: =-G7*Inputs!F34 -> -474.8186 | H16: =-H7*Inputs!G34 -> -486.68906
B17: (-) Change in NWC | D17: =-(D7-C7)*Inputs!C35 -> -25.559141 | E17: =-(E7-D7)*Inputs!D35 -> -27.070265 | F17: =-(F7-E7)*Inputs!E35 -> -28.657474 | G17: =-(G7-F7)*Inputs!F35 -> -30.326222 | H17: =-(H7-G7)*Inputs!G35 -> -32.082338
B18: Unlevered FCF | D18: =D14+D15+D16+D17 -> 1218.4112 | E18: =E14+E15+E16+E17 -> 1245.027 | F18: =F14+F15+F16+F17 -> 1273.2158 | G18: =G14+G15+G16+G17 -> 1303.057 | H18: =H14+H15+H16+H17 -> 1334.6354
B19: Discount factor | D19: =1/(1+WACC!$C$22)^(D5-0.5) -> 0.96628668 | E19: =1/(1+WACC!$C$22)^(E5-0.5) -> 0.90223149 | F19: =1/(1+WACC!$C$22)^(F5-0.5) -> 0.84242252 | G19: =1/(1+WACC!$C$22)^(G5-0.5) -> 0.78657829 | H19: =1/(1+WACC!$C$22)^(H5-0.5) -> 0.73443597
B20: PV of FCF | D20: =D18*D19 -> 1177.3345 | E20: =E18*E19 -> 1123.3025 | F20: =F18*F19 -> 1072.5857 | G20: =G18*G19 -> 1024.9563 | H20: =H18*H19 -> 980.20428
B22: Valuation | C22: Perpetuity | D22: Exit multiple
B23: WACC | C23: =WACC!$C$22 -> 0.070996405 | D23: =WACC!$C$22 -> 0.070996405
B24: Terminal growth / exit multiple | C24: =Inputs!$C$20 -> 0.025 | D24: =Inputs!$C$21 -> 10.620211
B25: Sum of PV of FCF | C25: =SUM(D20:H20) -> 5378.3834 | D25: =C25 -> 5378.3834
B26: Terminal value | C26: =H18*(1+C24)/(C23-C24) -> 29741.484 | D26: =H9*D24 -> 24102.625
B27: PV of terminal value | C27: =C26/(1+C23)^5 -> 21106.808 | D27: =D26/(1+D23)^5 -> 17105.048
B28: Enterprise value | C28: =C25+C27 -> 26485.192 | D28: =D25+D27 -> 22483.431
B29: (-) Net debt & minority | C29: =-(Inputs!$C$7-Inputs!$C$8+Inputs!$C$9) -> -5720.3152 | D29: =-(Inputs!$C$7-Inputs!$C$8+Inputs!$C$9) -> -5720.3152
B30: Equity value | C30: =C28+C29 -> 20764.876 | D30: =D28+D29 -> 16763.116
B31: Value per share | C31: =C30/Inputs!$C$6 -> 24.33103 | D31: =D30/Inputs!$C$6 -> 19.642008
B32: TV as % of EV | C32: =C27/C28 -> 0.79692866 | D32: =D27/D28 -> 0.76078458
B33: Implied exit multiple / growth | C33: =C26/H9 -> 13.104831 | D33: =(D26*D23-H18)/(D26+H18) -> 0.01480365
B36: Value per share: WACC vs terminal growth
B37: WACC ↓ / terminal growth → | C37: 0.015 | D37: 0.02 | E37: 0.025 | F37: 0.03 | G37: 0.035
B38: 0.061 | C38: =(SUMPRODUCT($D$18:$H$18/(1+$B38)^($D$5:$H$5-0.5))+$H$18*(1+C$37)/($B38-C$37)/(1+$B38)^5-(Inputs!$C$7-Inputs!$C$8+Inputs!$C$9))/Inputs!$C$6 -> 25.407906 | D38: =(SUMPRODUCT($D$18:$H$18/(1+$B38)^($D$5:$H$5-0.5))+$H$18*(1+D$37)/($B38-D$37)/(1+$B38)^5-(Inputs!$C$7-Inputs!$C$8+Inputs!$C$9))/Inputs!$C$6 -> 28.679509 | E38: =(SUMPRODUCT($D$18:$H$18/(1+$B38)^($D$5:$H$5-0.5))+$H$18*(1+E$37)/($B38-E$37)/(1+$B38)^5-(Inputs!$C$7-Inputs!$C$8+Inputs!$C$9))/Inputs!$C$6 -> 32.85989 | F38: =(SUMPRODUCT($D$18:$H$18/(1+$B38)^($D$5:$H$5-0.5))+$H$18*(1+F$37)/($B38-F$37)/(1+$B38)^5-(Inputs!$C$7-Inputs!$C$8+Inputs!$C$9))/Inputs!$C$6 -> 38.388782 | G38: =(SUMPRODUCT($D$18:$H$18/(1+$B38)^($D$5:$H$5-0.5))+$H$18*(1+G$37)/($B38-G$37)/(1+$B38)^5-(Inputs!$C$7-Inputs!$C$8+Inputs!$C$9))/Inputs!$C$6 -> 46.04417
B39: 0.066 | C39: =(SUMPRODUCT($D$18:$H$18/(1+$B39)^($D$5:$H$5-0.5))+$H$18*(1+C$37)/($B39-C$37)/(1+$B39)^5-(Inputs!$C$7-Inputs!$C$8+Inputs!$C$9))/Inputs!$C$6 -> 22.281019 | D39: =(SUMPRODUCT($D$18:$H$18/(1+$B39)^($D$5:$H$5-0.5))+$H$18*(1+D$37)/($B39-D$37)/(1+$B39)^5-(Inputs!$C$7-Inputs!$C$8+Inputs!$C$9))/Inputs!$C$6 -> 24.862132 | E39: =(SUMPRODUCT($D$18:$H$18/(1+$B39)^($D$5:$H$5-0.5))+$H$18*(1+E$37)/($B39-E$37)/(1+$B39)^5-(Inputs!$C$7-Inputs!$C$8+Inputs!$C$9))/Inputs!$C$6 -> 28.072784 | F39: =(SUMPRODUCT($D$18:$H$18/(1+$B39)^($D$5:$H$5-0.5))+$H$18*(1+F$37)/($B39-F$37)/(1+$B39)^5-(Inputs!$C$7-Inputs!$C$8+Inputs!$C$9))/Inputs!$C$6 -> 32.175284 | G39: =(SUMPRODUCT($D$18:$H$18/(1+$B39)^($D$5:$H$5-0.5))+$H$18*(1+G$37)/($B39-G$37)/(1+$B39)^5-(Inputs!$C$7-Inputs!$C$8+Inputs!$C$9))/Inputs!$C$6 -> 37.601172
B40: 0.071 | C40: =(SUMPRODUCT($D$18:$H$18/(1+$B40)^($D$5:$H$5-0.5))+$H$18*(1+C$37)/($B40-C$37)/(1+$B40)^5-(Inputs!$C$7-Inputs!$C$8+Inputs!$C$9))/Inputs!$C$6 -> 19.714498 | D40: =(SUMPRODUCT($D$18:$H$18/(1+$B40)^($D$5:$H$5-0.5))+$H$18*(1+D$37)/($B40-D$37)/(1+$B40)^5-(Inputs!$C$7-Inputs!$C$8+Inputs!$C$9))/Inputs!$C$6 -> 21.795382 | E40: =(SUMPRODUCT($D$18:$H$18/(1+$B40)^($D$5:$H$5-0.5))+$H$18*(1+E$37)/($B40-E$37)/(1+$B40)^5-(Inputs!$C$7-Inputs!$C$8+Inputs!$C$9))/Inputs!$C$6 -> 24.328631 | F40: =(SUMPRODUCT($D$18:$H$18/(1+$B40)^($D$5:$H$5-0.5))+$H$18*(1+F$37)/($B40-F$37)/(1+$B40)^5-(Inputs!$C$7-Inputs!$C$8+Inputs!$C$9))/Inputs!$C$6 -> 27.479746 | G40: =(SUMPRODUCT($D$18:$H$18/(1+$B40)^($D$5:$H$5-0.5))+$H$18*(1+G$37)/($B40-G$37)/(1+$B40)^5-(Inputs!$C$7-Inputs!$C$8+Inputs!$C$9))/Inputs!$C$6 -> 31.50617
B41: 0.076 | C41: =(SUMPRODUCT($D$18:$H$18/(1+$B41)^($D$5:$H$5-0.5))+$H$18*(1+C$37)/($B41-C$37)/(1+$B41)^5-(Inputs!$C$7-Inputs!$C$8+Inputs!$C$9))/Inputs!$C$6 -> 17.570464 | D41: =(SUMPRODUCT($D$18:$H$18/(1+$B41)^($D$5:$H$5-0.5))+$H$18*(1+D$37)/($B41-D$37)/(1+$B41)^5-(Inputs!$C$7-Inputs!$C$8+Inputs!$C$9))/Inputs!$C$6 -> 19.278107 | E41: =(SUMPRODUCT($D$18:$H$18/(1+$B41)^($D$5:$H$5-0.5))+$H$18*(1+E$37)/($B41-E$37)/(1+$B41)^5-(Inputs!$C$7-Inputs!$C$8+Inputs!$C$9))/Inputs!$C$6 -> 21.32058 | F41: =(SUMPRODUCT($D$18:$H$18/(1+$B41)^($D$5:$H$5-0.5))+$H$18*(1+F$37)/($B41-F$37)/(1+$B41)^5-(Inputs!$C$7-Inputs!$C$8+Inputs!$C$9))/Inputs!$C$6 -> 23.80707 | G41: =(SUMPRODUCT($D$18:$H$18/(1+$B41)^($D$5:$H$5-0.5))+$H$18*(1+G$37)/($B41-G$37)/(1+$B41)^5-(Inputs!$C$7-Inputs!$C$8+Inputs!$C$9))/Inputs!$C$6 -> 26.900021
B42: 0.081 | C42: =(SUMPRODUCT($D$18:$H$18/(1+$B42)^($D$5:$H$5-0.5))+$H$18*(1+C$37)/($B42-C$37)/(1+$B42)^5-(Inputs!$C$7-Inputs!$C$8+Inputs!$C$9))/Inputs!$C$6 -> 15.752822 | D42: =(SUMPRODUCT($D$18:$H$18/(1+$B42)^($D$5:$H$5-0.5))+$H$18*(1+D$37)/($B42-D$37)/(1+$B42)^5-(Inputs!$C$7-Inputs!$C$8+Inputs!$C$9))/Inputs!$C$6 -> 17.175109 | E42: =(SUMPRODUCT($D$18:$H$18/(1+$B42)^($D$5:$H$5-0.5))+$H$18*(1+E$37)/($B42-E$37)/(1+$B42)^5-(Inputs!$C$7-Inputs!$C$8+Inputs!$C$9))/Inputs!$C$6 -> 18.851376 | F42: =(SUMPRODUCT($D$18:$H$18/(1+$B42)^($D$5:$H$5-0.5))+$H$18*(1+F$37)/($B42-F$37)/(1+$B42)^5-(Inputs!$C$7-Inputs!$C$8+Inputs!$C$9))/Inputs!$C$6 -> 20.856322 | G42: =(SUMPRODUCT($D$18:$H$18/(1+$B42)^($D$5:$H$5-0.5))+$H$18*(1+G$37)/($B42-G$37)/(1+$B42)^5-(Inputs!$C$7-Inputs!$C$8+Inputs!$C$9))/Inputs!$C$6 -> 23.297127
B45: Value per share: WACC vs exit multiple
B46: WACC ↓ / exit multiple → | C46: 8.6 | D46: 9.6 | E46: 10.6 | F46: 11.6 | G46: 12.6
B47: 0.061 | C47: =(SUMPRODUCT($D$18:$H$18/(1+$B47)^($D$5:$H$5-0.5))+$H$9*C$46/(1+$B47)^5-(Inputs!$C$7-Inputs!$C$8+Inputs!$C$9))/Inputs!$C$6 -> 16.753062 | D47: =(SUMPRODUCT($D$18:$H$18/(1+$B47)^($D$5:$H$5-0.5))+$H$9*D$46/(1+$B47)^5-(Inputs!$C$7-Inputs!$C$8+Inputs!$C$9))/Inputs!$C$6 -> 18.730876 | E47: =(SUMPRODUCT($D$18:$H$18/(1+$B47)^($D$5:$H$5-0.5))+$H$9*E$46/(1+$B47)^5-(Inputs!$C$7-Inputs!$C$8+Inputs!$C$9))/Inputs!$C$6 -> 20.70869 | F47: =(SUMPRODUCT($D$18:$H$18/(1+$B47)^($D$5:$H$5-0.5))+$H$9*F$46/(1+$B47)^5-(Inputs!$C$7-Inputs!$C$8+Inputs!$C$9))/Inputs!$C$6 -> 22.686504 | G47: =(SUMPRODUCT($D$18:$H$18/(1+$B47)^($D$5:$H$5-0.5))+$H$9*G$46/(1+$B47)^5-(Inputs!$C$7-Inputs!$C$8+Inputs!$C$9))/Inputs!$C$6 -> 24.664318
B48: 0.066 | C48: =(SUMPRODUCT($D$18:$H$18/(1+$B48)^($D$5:$H$5-0.5))+$H$9*C$46/(1+$B48)^5-(Inputs!$C$7-Inputs!$C$8+Inputs!$C$9))/Inputs!$C$6 -> 16.28488 | D48: =(SUMPRODUCT($D$18:$H$18/(1+$B48)^($D$5:$H$5-0.5))+$H$9*D$46/(1+$B48)^5-(Inputs!$C$7-Inputs!$C$8+Inputs!$C$9))/Inputs!$C$6 -> 18.216743 | E48: =(SUMPRODUCT($D$18:$H$18/(1+$B48)^($D$5:$H$5-0.5))+$H$9*E$46/(1+$B48)^5-(Inputs!$C$7-Inputs!$C$8+Inputs!$C$9))/Inputs!$C$6 -> 20.148606 | F48: =(SUMPRODUCT($D$18:$H$18/(1+$B48)^($D$5:$H$5-0.5))+$H$9*F$46/(1+$B48)^5-(Inputs!$C$7-Inputs!$C$8+Inputs!$C$9))/Inputs!$C$6 -> 22.080469 | G48: =(SUMPRODUCT($D$18:$H$18/(1+$B48)^($D$5:$H$5-0.5))+$H$9*G$46/(1+$B48)^5-(Inputs!$C$7-Inputs!$C$8+Inputs!$C$9))/Inputs!$C$6 -> 24.012332
...

Sheet LBO
B2: LBO ability-to-pay ($mm)
B3: Change the offer price on the Inputs sheet (or Goal Seek IRR) to test other prices.
B5: Offer price per share | C5: =Inputs!$C$28 -> 13.133348
B6: Equity purchase price | C6: =C5*Inputs!$C$6 -> 11208.418
B7: (+) Net debt & minority refinanced | C7: =(Inputs!$C$7-Inputs!$C$8+Inputs!$C$9) -> 5720.3152
B8: Entry enterprise value | C8: =C6+C7 -> 16928.733
B9: Entry EV / LTM EBITDA | C9: =C8/Inputs!$C$11 -> 8.1246515
B10: Transaction fees | C10: =C8*Inputs!$C$27 -> 338.57466
B11: New debt raised | C11: =Inputs!$C$25*Inputs!$C$11 -> 10418.129
B12: Sponsor equity | C12: =C8+C10-C11 -> 6849.179
B13: Premium to current price | C13: =C5/Inputs!$C$5-1 -> -0.34333259
C16: Entry | D16: FY2026E | E16: FY2027E | F16: FY2028E | G16: FY2029E | H16: FY2030E
B17: EBITDA | D17: =DCF!D9 -> 2065.6769 | E17: =DCF!E9 -> 2112.383 | F17: =DCF!F9 -> 2161.8277 | G17: =DCF!G9 -> 2214.1515 | H17: =DCF!H9 -> 2269.5053
B18: D&A | D18: =DCF!D11 -> 419.03384 | E18: =DCF!E11 -> 428.50844 | F18: =DCF!F11 -> 438.53855 | G18: =DCF!G11 -> 449.15273 | H18: =DCF!H11 -> 460.38155
B19: Interest | D19: =C25*Inputs!$C$26 -> 885.54095 | E19: =D25*Inputs!$C$26 -> 839.93465 | F19: =E25*Inputs!$C$26 -> 789.08108 | G19: =F25*Inputs!$C$26 -> 732.50309 | H19: =G25*Inputs!$C$26 -> 669.68558
B20: Taxes | D20: =MAX(0,D17-D18-D19)*Inputs!$C$19 -> 175.05349 | E20: =MAX(0,E17-E18-E19)*Inputs!$C$19 -> 194.10619 | F20: =MAX(0,F17-F18-F19)*Inputs!$C$19 -> 214.86785 | G20: =MAX(0,G17-G18-G19)*Inputs!$C$19 -> 237.47401 | H20: =MAX(0,H17-H18-H19)*Inputs!$C$19 -> 262.07078
B21: Capex | D21: =-DCF!D16 -> 442.97863 | E21: =-DCF!E16 -> 452.99463 | F21: =-DCF!F16 -> 463.5979 | G21: =-DCF!G16 -> 474.8186 | H21: =-DCF!H16 -> 486.68906
B22: Change in NWC | D22: =-DCF!D17 -> 25.559141 | E22: =-DCF!E17 -> 27.070265 | F22: =-DCF!F17 -> 28.657474 | G22: =-DCF!G17 -> 30.326222 | H22: =-DCF!H17 -> 32.082338
B23: Levered FCF | D23: =D17-D19-D20-D21-D22 -> 536.5447 | E23: =E17-E19-E20-E21-E22 -> 598.2773 | F23: =F17-F19-F20-F21-F22 -> 665.62337 | G23: =G17-G19-G20-G21-G22 -> 739.0296 | H23: =H17-H19-H20-H21-H22 -> 818.97755
B24: Debt repayment | D24: =MIN(C25,MAX(D23,0)) -> 536.5447 | E24: =MIN(D25,MAX(E23,0)) -> 598.2773 | F24: =MIN(E25,MAX(F23,0)) -> 665.62337 | G24: =MIN(F25,MAX(G23,0)) -> 739.0296 | H24: =MIN(G25,MAX(H23,0)) -> 818.97755
B25: Debt (end) | C25: =C11 -> 10418.129 | D25: =C25-D24 -> 9881.5841 | E25: =D25-E24 -> 9283.3068 | F25: =E25-F24 -> 8617.6834 | G25: =F25-G24 -> 7878.6538 | H25: =G25-H24 -> 7059.6763
B26: Cash (end) | C26: 0 | D26: =C26+D23-D24 -> 0 | E26: =D26+E23-E24 -> 0 | F26: =E26+F23-F24 -> 0 | G26: =F26+G23-G24 -> 0 | H26: =G26+H23-H24 -> 0
B27: Net debt / EBITDA | D27: =(D25-D26)/D17 -> 4.7837027 | E27: =(E25-E26)/E17 -> 4.3947081 | F27: =(F25-F26)/F17 -> 3.9862953 | G27: =(G25-G26)/G17 -> 3.5583174 | H27: =(H25-H26)/H17 -> 3.1106675
B30: Exit EV (exit multiple x exit EBITDA) | C30: =Inputs!$C$21*H17 -> 24102.625
B31: (-) Debt | C31: =-H25 -> -7059.6763
B32: (+) Cash | C32: =H26 -> 0
B33: Exit equity value | C33: =SUM(C30:C32) -> 17042.949
B34: MOIC | C34: =C33/C12 -> 2.48832
B35: IRR | C35: =C34^(1/5)-1 -> 0.2

Sheet Football Field
B2: Valuation summary: value per share
B4: Methodology | C4: Low | D4: High | E4: Spread
B5: 52-week trading range | C5: 17.572607 | D5: 22.300815 | E5: =D5-C5 -> 4.7282088
B6: Analyst price targets | C6: 17.6 | D6: 24.4 | E6: =D6-C6 -> 6.8
B7: EV / LTM EBITDA | C7: =Comps!$D$19 -> 17.280713 | D7: =Comps!$E$19 -> 20.5586 | E7: =D7-C7 -> 3.2778873
B8: P / NTM EPS | C8: =Comps!$D$20 -> 16.841539 | D8: =Comps!$E$20 -> 21.379679 | E8: =D8-C8 -> 4.5381399
B9: Precedent transactions | C9: 21.37415 | D9: 28.454404 | E9: =D9-C9 -> 7.0802543
B10: Premiums paid | C10: 24 | D10: 28 | E10: =D10-C10 -> 4
B11: DCF – perpetuity growth | C11: =MIN(DCF!D39:F41) -> 19.278107 | D11: =MAX(DCF!D39:F41) -> 32.175284 | E11: =D11-C11 -> 12.897178
B12: DCF – exit multiple | C12: =MIN(DCF!D48:F50) -> 17.229088 | D12: =MAX(DCF!D48:F50) -> 22.080469 | E12: =D12-C12 -> 4.8513814
B13: LBO (20–25% IRR) | C13: 11.022324 | D13: 13.669787 | E13: =D13-C13 -> 2.6474629
B15: Current share price | C15: =Inputs!$C$5 -> 20

Sheet Buyers
B2: Potential strategic acquirers
B4: Ticker | C4: Company | D4: Mkt cap ($mm) | E4: Net debt / EBITDA | F4: Deal size / buyer mkt cap | G4: PF leverage (all-debt) | H4: Buyer P/E NTM | I4: All-cash feasible | J4: All-stock EPS
B5: BUY-B.DEMO | C5: Buy-B Corp. (synthetic) | D5: 176319.94 | E5: 1.755593 | F5: 0.15828921 | G5: 3.0133265 | H5: 17.997537 | I5: Yes | J5: Dilutive
B6: BUY-A.DEMO | C6: Buy-A Corp. (synthetic) | D6: 88683.221 | E6: 1.8738033 | F6: 0.31471054 | G6: 4.2491321 | H6: 18.763486 | I6: Stretch | J6: Dilutive
B7: BUY-D.DEMO | C7: Buy-D Corp. (synthetic) | D7: 72901.198 | E7: 2.7157107 | F7: 0.38284068 | G7: 4.7941559 | H7: 16.657148 | I7: Stretch | J7: Dilutive
B8: BUY-C.DEMO | C8: Buy-C Corp. (synthetic) | D8: 37264.987 | E8: 1.418132 | F8: 0.74894818 | G8: 6.3348238 | H8: 19.79638 | I8: Stretch | J8: Dilutive
B9: PEER-A.DEMO | C9: Peer-A Corp. (synthetic) | D9: 30922.013 | E9: 2.6569744 | F9: 0.90257851 | G9: 6.4066723 | H9: 14.753474 | I9: Stretch | J9: Dilutive
